2021-11-06 22:27:29,438 INFO    MainThread:31743 [internal.py:wandb_internal():88] W&B internal server running at pid: 31743, started at: 2021-11-06 22:27:29.437796
2021-11-06 22:27:29,440 DEBUG   HandlerThread:31743 [handler.py:handle_request():130] handle_request: check_version
2021-11-06 22:27:29,440 INFO    WriterThread:31743 [datastore.py:open_for_write():77] open: /home/cj1223/work/GraphMerge/wandb/run-20211106_222728-1yapfjc8/run-1yapfjc8.wandb
2021-11-06 22:27:29,441 DEBUG   SenderThread:31743 [sender.py:send():185] send: header
2021-11-06 22:27:29,441 DEBUG   SenderThread:31743 [sender.py:send_request():199] send_request: check_version
2021-11-06 22:27:34,442 DEBUG   SenderThread:31743 [sender.py:send():185] send: run
2021-11-06 22:27:52,791 ERROR   SenderThread:31743 [retry.py:__call__():126] Retry attempt failed:
Traceback (most recent call last):
  File "/home/cj1223/.conda/envs/juptorch/lib/python3.9/site-packages/urllib3/connection.py", line 169, in _new_conn
    conn = connection.create_connection(
  File "/home/cj1223/.conda/envs/juptorch/lib/python3.9/site-packages/urllib3/util/connection.py", line 73, in create_connection
    for res in socket.getaddrinfo(host, port, family, socket.SOCK_STREAM):
  File "/home/cj1223/.conda/envs/juptorch/lib/python3.9/socket.py", line 954, in getaddrinfo
    for res in _socket.getaddrinfo(host, port, family, type, proto, flags):
socket.gaierror: [Errno -2] Name or service not known

During handling of the above exception, another exception occurred:

Traceback (most recent call last):
  File "/home/cj1223/.conda/envs/juptorch/lib/python3.9/site-packages/urllib3/connectionpool.py", line 699, in urlopen
    httplib_response = self._make_request(
  File "/home/cj1223/.conda/envs/juptorch/lib/python3.9/site-packages/urllib3/connectionpool.py", line 382, in _make_request
    self._validate_conn(conn)
  File "/home/cj1223/.conda/envs/juptorch/lib/python3.9/site-packages/urllib3/connectionpool.py", line 1010, in _validate_conn
    conn.connect()
  File "/home/cj1223/.conda/envs/juptorch/lib/python3.9/site-packages/urllib3/connection.py", line 353, in connect
    conn = self._new_conn()
  File "/home/cj1223/.conda/envs/juptorch/lib/python3.9/site-packages/urllib3/connection.py", line 181, in _new_conn
    raise NewConnectionError(
urllib3.exceptions.NewConnectionError: <urllib3.connection.HTTPSConnection object at 0x2ad1f1cbfe20>: Failed to establish a new connection: [Errno -2] Name or service not known

During handling of the above exception, another exception occurred:

Traceback (most recent call last):
  File "/home/cj1223/.conda/envs/juptorch/lib/python3.9/site-packages/requests/adapters.py", line 439, in send
    resp = conn.urlopen(
  File "/home/cj1223/.conda/envs/juptorch/lib/python3.9/site-packages/urllib3/connectionpool.py", line 755, in urlopen
    retries = retries.increment(
  File "/home/cj1223/.conda/envs/juptorch/lib/python3.9/site-packages/urllib3/util/retry.py", line 574, in increment
    raise MaxRetryError(_pool, url, error or ResponseError(cause))
urllib3.exceptions.MaxRetryError: HTTPSConnectionPool(host='api.wandb.ai', port=443): Max retries exceeded with url: /graphql (Caused by NewConnectionError('<urllib3.connection.HTTPSConnection object at 0x2ad1f1cbfe20>: Failed to establish a new connection: [Errno -2] Name or service not known'))

During handling of the above exception, another exception occurred:

Traceback (most recent call last):
  File "/home/cj1223/.conda/envs/juptorch/lib/python3.9/site-packages/wandb/sdk/lib/retry.py", line 102, in __call__
    result = self._call_fn(*args, **kwargs)
  File "/home/cj1223/.conda/envs/juptorch/lib/python3.9/site-packages/wandb/sdk/internal/internal_api.py", line 141, in execute
    return self.client.execute(*args, **kwargs)
  File "/home/cj1223/.conda/envs/juptorch/lib/python3.9/site-packages/wandb/vendor/gql-0.2.0/gql/client.py", line 52, in execute
    result = self._get_result(document, *args, **kwargs)
  File "/home/cj1223/.conda/envs/juptorch/lib/python3.9/site-packages/wandb/vendor/gql-0.2.0/gql/client.py", line 60, in _get_result
    return self.transport.execute(document, *args, **kwargs)
  File "/home/cj1223/.conda/envs/juptorch/lib/python3.9/site-packages/wandb/vendor/gql-0.2.0/gql/transport/requests.py", line 38, in execute
    request = requests.post(self.url, **post_args)
  File "/home/cj1223/.conda/envs/juptorch/lib/python3.9/site-packages/requests/api.py", line 117, in post
    return request('post', url, data=data, json=json, **kwargs)
  File "/home/cj1223/.conda/envs/juptorch/lib/python3.9/site-packages/requests/api.py", line 61, in request
    return session.request(method=method, url=url, **kwargs)
  File "/home/cj1223/.conda/envs/juptorch/lib/python3.9/site-packages/requests/sessions.py", line 542, in request
    resp = self.send(prep, **send_kwargs)
  File "/home/cj1223/.conda/envs/juptorch/lib/python3.9/site-packages/requests/sessions.py", line 655, in send
    r = adapter.send(request, **kwargs)
  File "/home/cj1223/.conda/envs/juptorch/lib/python3.9/site-packages/requests/adapters.py", line 516, in send
    raise ConnectionError(e, request=request)
requests.exceptions.ConnectionError: HTTPSConnectionPool(host='api.wandb.ai', port=443): Max retries exceeded with url: /graphql (Caused by NewConnectionError('<urllib3.connection.HTTPSConnection object at 0x2ad1f1cbfe20>: Failed to establish a new connection: [Errno -2] Name or service not known'))
2021-11-06 22:28:03,439 DEBUG   HandlerThread:31743 [handler.py:handle_request():130] handle_request: shutdown
2021-11-06 22:28:03,439 INFO    HandlerThread:31743 [handler.py:finish():731] shutting down handler
2021-11-06 22:28:03,442 INFO    WriterThread:31743 [datastore.py:close():281] close: /home/cj1223/work/GraphMerge/wandb/run-20211106_222728-1yapfjc8/run-1yapfjc8.wandb
2021-11-06 22:28:17,195 INFO    MainThread:31743 [internal.py:handle_exit():78] Internal process exited
