2021-11-06 19:48:03,862 INFO    MainThread:23400 [wandb_setup.py:_flush():71] setting env: {}
2021-11-06 19:48:03,863 INFO    MainThread:23400 [wandb_setup.py:_flush():71] setting login settings: {}
2021-11-06 19:48:03,863 INFO    MainThread:23400 [wandb_setup.py:_flush():71] setting login settings: {'api_key': 'b5b917a9390932e56fccfcbff6f528ccd85c44bf'}
2021-11-06 19:48:03,863 INFO    MainThread:23400 [wandb_init.py:_log_setup():357] Logging user logs to /home/cj1223/work/GraphMerge/wandb/run-20211106_194803-3qwviufp/logs/debug.log
2021-11-06 19:48:03,863 INFO    MainThread:23400 [wandb_init.py:_log_setup():358] Logging internal logs to /home/cj1223/work/GraphMerge/wandb/run-20211106_194803-3qwviufp/logs/debug-internal.log
2021-11-06 19:48:03,863 INFO    MainThread:23400 [wandb_init.py:init():390] calling init triggers
2021-11-06 19:48:03,863 INFO    MainThread:23400 [wandb_init.py:init():395] wandb.init called with sweep_config: {}
config: {'experiment': 'GraphMerge', 'group': 'test', 'model_name': 'Sage', 'wandblog': True, 'run_params': {'n_epochs': 100, 'n_trials': 20, 'batch_size': 512, 'learning_rate': 0.003, 'val_epoch': 2, 'loss_func': 'L2', 'metrics': 'scatter', 'performance_plot': 'SAM_base', 'shuffle': True, 'save': True}, 'hyper_params': {'hidden_channels': 32, 'conv_layers': 2, 'conv_activation': 'relu', 'decode_layers': 1, 'dropout': 0.02, 'layernorm': True}, 'data_params': {'case': 'test_all_smass', 'split': 0.8}, 'experiment_name': 'test'}
2021-11-06 19:48:03,864 INFO    MainThread:23400 [wandb_init.py:init():435] starting backend
2021-11-06 19:48:03,864 INFO    MainThread:23400 [backend.py:_multiprocessing_setup():94] multiprocessing start_methods=fork,spawn,forkserver, using: fork
2021-11-06 19:48:03,892 INFO    MainThread:23400 [backend.py:ensure_launched():198] starting backend process...
2021-11-06 19:48:03,914 INFO    MainThread:23400 [backend.py:ensure_launched():203] started backend process with pid: 24096
2021-11-06 19:48:03,918 INFO    MainThread:23400 [wandb_init.py:init():444] backend started and connected
2021-11-06 19:48:03,919 INFO    MainThread:24096 [internal.py:wandb_internal():88] W&B internal server running at pid: 24096, started at: 2021-11-06 19:48:03.917414
2021-11-06 19:48:03,921 INFO    MainThread:23400 [wandb_init.py:init():503] updated telemetry
2021-11-06 19:48:03,929 INFO    WriterThread:24096 [datastore.py:open_for_write():77] open: /home/cj1223/work/GraphMerge/wandb/run-20211106_194803-3qwviufp/run-3qwviufp.wandb
2021-11-06 19:48:03,981 INFO    MainThread:23400 [wandb_init.py:init():533] communicating current version
2021-11-06 19:48:08,982 INFO    MainThread:23400 [wandb_init.py:init():548] communicating run to backend with 30 second timeout
2021-11-06 19:48:17,179 ERROR   Thread-1  :23400 [retry.py:__call__():126] Retry attempt failed:
Traceback (most recent call last):
  File "/home/cj1223/.conda/envs/juptorch/lib/python3.9/site-packages/urllib3/connection.py", line 169, in _new_conn
    conn = connection.create_connection(
  File "/home/cj1223/.conda/envs/juptorch/lib/python3.9/site-packages/urllib3/util/connection.py", line 73, in create_connection
    for res in socket.getaddrinfo(host, port, family, socket.SOCK_STREAM):
  File "/home/cj1223/.conda/envs/juptorch/lib/python3.9/socket.py", line 954, in getaddrinfo
    for res in _socket.getaddrinfo(host, port, family, type, proto, flags):
socket.gaierror: [Errno -2] Name or service not known

During handling of the above exception, another exception occurred:

Traceback (most recent call last):
  File "/home/cj1223/.conda/envs/juptorch/lib/python3.9/site-packages/urllib3/connectionpool.py", line 699, in urlopen
    httplib_response = self._make_request(
  File "/home/cj1223/.conda/envs/juptorch/lib/python3.9/site-packages/urllib3/connectionpool.py", line 382, in _make_request
    self._validate_conn(conn)
  File "/home/cj1223/.conda/envs/juptorch/lib/python3.9/site-packages/urllib3/connectionpool.py", line 1010, in _validate_conn
    conn.connect()
  File "/home/cj1223/.conda/envs/juptorch/lib/python3.9/site-packages/urllib3/connection.py", line 353, in connect
    conn = self._new_conn()
  File "/home/cj1223/.conda/envs/juptorch/lib/python3.9/site-packages/urllib3/connection.py", line 181, in _new_conn
    raise NewConnectionError(
urllib3.exceptions.NewConnectionError: <urllib3.connection.HTTPSConnection object at 0x2adee5b884c0>: Failed to establish a new connection: [Errno -2] Name or service not known

During handling of the above exception, another exception occurred:

Traceback (most recent call last):
  File "/home/cj1223/.conda/envs/juptorch/lib/python3.9/site-packages/requests/adapters.py", line 439, in send
    resp = conn.urlopen(
  File "/home/cj1223/.conda/envs/juptorch/lib/python3.9/site-packages/urllib3/connectionpool.py", line 755, in urlopen
    retries = retries.increment(
  File "/home/cj1223/.conda/envs/juptorch/lib/python3.9/site-packages/urllib3/util/retry.py", line 574, in increment
    raise MaxRetryError(_pool, url, error or ResponseError(cause))
urllib3.exceptions.MaxRetryError: HTTPSConnectionPool(host='api.wandb.ai', port=443): Max retries exceeded with url: /graphql (Caused by NewConnectionError('<urllib3.connection.HTTPSConnection object at 0x2adee5b884c0>: Failed to establish a new connection: [Errno -2] Name or service not known'))

During handling of the above exception, another exception occurred:

Traceback (most recent call last):
  File "/home/cj1223/.conda/envs/juptorch/lib/python3.9/site-packages/wandb/sdk/lib/retry.py", line 102, in __call__
    result = self._call_fn(*args, **kwargs)
  File "/home/cj1223/.conda/envs/juptorch/lib/python3.9/site-packages/wandb/sdk/internal/internal_api.py", line 141, in execute
    return self.client.execute(*args, **kwargs)
  File "/home/cj1223/.conda/envs/juptorch/lib/python3.9/site-packages/wandb/vendor/gql-0.2.0/gql/client.py", line 52, in execute
    result = self._get_result(document, *args, **kwargs)
  File "/home/cj1223/.conda/envs/juptorch/lib/python3.9/site-packages/wandb/vendor/gql-0.2.0/gql/client.py", line 60, in _get_result
    return self.transport.execute(document, *args, **kwargs)
  File "/home/cj1223/.conda/envs/juptorch/lib/python3.9/site-packages/wandb/vendor/gql-0.2.0/gql/transport/requests.py", line 38, in execute
    request = requests.post(self.url, **post_args)
  File "/home/cj1223/.conda/envs/juptorch/lib/python3.9/site-packages/requests/api.py", line 117, in post
    return request('post', url, data=data, json=json, **kwargs)
  File "/home/cj1223/.conda/envs/juptorch/lib/python3.9/site-packages/requests/api.py", line 61, in request
    return session.request(method=method, url=url, **kwargs)
  File "/home/cj1223/.conda/envs/juptorch/lib/python3.9/site-packages/requests/sessions.py", line 542, in request
    resp = self.send(prep, **send_kwargs)
  File "/home/cj1223/.conda/envs/juptorch/lib/python3.9/site-packages/requests/sessions.py", line 655, in send
    r = adapter.send(request, **kwargs)
  File "/home/cj1223/.conda/envs/juptorch/lib/python3.9/site-packages/requests/adapters.py", line 516, in send
    raise ConnectionError(e, request=request)
requests.exceptions.ConnectionError: HTTPSConnectionPool(host='api.wandb.ai', port=443): Max retries exceeded with url: /graphql (Caused by NewConnectionError('<urllib3.connection.HTTPSConnection object at 0x2adee5b884c0>: Failed to establish a new connection: [Errno -2] Name or service not known'))
2021-11-06 19:48:20,233 ERROR   SenderThread:24096 [retry.py:__call__():126] Retry attempt failed:
Traceback (most recent call last):
  File "/home/cj1223/.conda/envs/juptorch/lib/python3.9/site-packages/urllib3/connection.py", line 169, in _new_conn
    conn = connection.create_connection(
  File "/home/cj1223/.conda/envs/juptorch/lib/python3.9/site-packages/urllib3/util/connection.py", line 73, in create_connection
    for res in socket.getaddrinfo(host, port, family, socket.SOCK_STREAM):
  File "/home/cj1223/.conda/envs/juptorch/lib/python3.9/socket.py", line 954, in getaddrinfo
    for res in _socket.getaddrinfo(host, port, family, type, proto, flags):
socket.gaierror: [Errno -2] Name or service not known

During handling of the above exception, another exception occurred:

Traceback (most recent call last):
  File "/home/cj1223/.conda/envs/juptorch/lib/python3.9/site-packages/urllib3/connectionpool.py", line 699, in urlopen
    httplib_response = self._make_request(
  File "/home/cj1223/.conda/envs/juptorch/lib/python3.9/site-packages/urllib3/connectionpool.py", line 382, in _make_request
    self._validate_conn(conn)
  File "/home/cj1223/.conda/envs/juptorch/lib/python3.9/site-packages/urllib3/connectionpool.py", line 1010, in _validate_conn
    conn.connect()
  File "/home/cj1223/.conda/envs/juptorch/lib/python3.9/site-packages/urllib3/connection.py", line 353, in connect
    conn = self._new_conn()
  File "/home/cj1223/.conda/envs/juptorch/lib/python3.9/site-packages/urllib3/connection.py", line 181, in _new_conn
    raise NewConnectionError(
urllib3.exceptions.NewConnectionError: <urllib3.connection.HTTPSConnection object at 0x2adee61c9040>: Failed to establish a new connection: [Errno -2] Name or service not known

During handling of the above exception, another exception occurred:

Traceback (most recent call last):
  File "/home/cj1223/.conda/envs/juptorch/lib/python3.9/site-packages/requests/adapters.py", line 439, in send
    resp = conn.urlopen(
  File "/home/cj1223/.conda/envs/juptorch/lib/python3.9/site-packages/urllib3/connectionpool.py", line 755, in urlopen
    retries = retries.increment(
  File "/home/cj1223/.conda/envs/juptorch/lib/python3.9/site-packages/urllib3/util/retry.py", line 574, in increment
    raise MaxRetryError(_pool, url, error or ResponseError(cause))
urllib3.exceptions.MaxRetryError: HTTPSConnectionPool(host='api.wandb.ai', port=443): Max retries exceeded with url: /graphql (Caused by NewConnectionError('<urllib3.connection.HTTPSConnection object at 0x2adee61c9040>: Failed to establish a new connection: [Errno -2] Name or service not known'))

During handling of the above exception, another exception occurred:

Traceback (most recent call last):
  File "/home/cj1223/.conda/envs/juptorch/lib/python3.9/site-packages/wandb/sdk/lib/retry.py", line 102, in __call__
    result = self._call_fn(*args, **kwargs)
  File "/home/cj1223/.conda/envs/juptorch/lib/python3.9/site-packages/wandb/sdk/internal/internal_api.py", line 141, in execute
    return self.client.execute(*args, **kwargs)
  File "/home/cj1223/.conda/envs/juptorch/lib/python3.9/site-packages/wandb/vendor/gql-0.2.0/gql/client.py", line 52, in execute
    result = self._get_result(document, *args, **kwargs)
  File "/home/cj1223/.conda/envs/juptorch/lib/python3.9/site-packages/wandb/vendor/gql-0.2.0/gql/client.py", line 60, in _get_result
    return self.transport.execute(document, *args, **kwargs)
  File "/home/cj1223/.conda/envs/juptorch/lib/python3.9/site-packages/wandb/vendor/gql-0.2.0/gql/transport/requests.py", line 38, in execute
    request = requests.post(self.url, **post_args)
  File "/home/cj1223/.conda/envs/juptorch/lib/python3.9/site-packages/requests/api.py", line 117, in post
    return request('post', url, data=data, json=json, **kwargs)
  File "/home/cj1223/.conda/envs/juptorch/lib/python3.9/site-packages/requests/api.py", line 61, in request
    return session.request(method=method, url=url, **kwargs)
  File "/home/cj1223/.conda/envs/juptorch/lib/python3.9/site-packages/requests/sessions.py", line 542, in request
    resp = self.send(prep, **send_kwargs)
  File "/home/cj1223/.conda/envs/juptorch/lib/python3.9/site-packages/requests/sessions.py", line 655, in send
    r = adapter.send(request, **kwargs)
  File "/home/cj1223/.conda/envs/juptorch/lib/python3.9/site-packages/requests/adapters.py", line 516, in send
    raise ConnectionError(e, request=request)
requests.exceptions.ConnectionError: HTTPSConnectionPool(host='api.wandb.ai', port=443): Max retries exceeded with url: /graphql (Caused by NewConnectionError('<urllib3.connection.HTTPSConnection object at 0x2adee61c9040>: Failed to establish a new connection: [Errno -2] Name or service not known'))
2021-11-06 19:48:38,984 INFO    MainThread:23400 [interface.py:_communicate_run():903] couldn't get run from backend
2021-11-06 19:48:38,984 ERROR   MainThread:23400 [wandb_init.py:init():553] backend process timed out
2021-11-06 19:48:38,985 ERROR   MainThread:23400 [wandb_init.py:init():562] encountered error: Error communicating with wandb process
2021-11-06 19:48:38,986 INFO    HandlerThread:24096 [handler.py:finish():731] shutting down handler
2021-11-06 19:48:38,992 INFO    WriterThread:24096 [datastore.py:close():281] close: /home/cj1223/work/GraphMerge/wandb/run-20211106_194803-3qwviufp/run-3qwviufp.wandb
2021-11-06 19:48:42,867 WARNING MainThread:23400 [wandb_init.py:init():891] interrupted
Traceback (most recent call last):
  File "/home/cj1223/.conda/envs/juptorch/lib/python3.9/site-packages/wandb/sdk/wandb_init.py", line 870, in init
    run = wi.init()
  File "/home/cj1223/.conda/envs/juptorch/lib/python3.9/site-packages/wandb/sdk/wandb_init.py", line 566, in init
    backend.cleanup()
  File "/home/cj1223/.conda/envs/juptorch/lib/python3.9/site-packages/wandb/sdk/backend/backend.py", line 229, in cleanup
    self.wandb_process.join()
  File "/home/cj1223/.conda/envs/juptorch/lib/python3.9/multiprocessing/process.py", line 149, in join
    res = self._popen.wait(timeout)
  File "/home/cj1223/.conda/envs/juptorch/lib/python3.9/multiprocessing/popen_fork.py", line 43, in wait
    return self.poll(os.WNOHANG if timeout == 0.0 else 0)
  File "/home/cj1223/.conda/envs/juptorch/lib/python3.9/multiprocessing/popen_fork.py", line 27, in poll
    pid, sts = os.waitpid(self.pid, flag)
KeyboardInterrupt
